<?xml version="1.0"?>
<robot name="my_robo">
	<link name="base_link">
		<visual>
			<geometry>
				<box size="0.400 0.200 0.100"/>
			</geometry>
		</visual>
		<collision>
			<geometry>
				<box size="0.400 0.200 0.100"/>
			</geometry>
		</collision>
		<inertial>
			<origin xyz="0 0 0"/>
			<mass value="0.500"/>
			<inertia ixx="0.0020833333" ixy="0" ixz="0" iyy="0.0070833333" iyz="0" izz="0.0083333333"/>
		</inertial>
	</link>


	<link name="left_wheel_link">
		<visual>
			<geometry>
				<cylinder radius="0.1" length="0.05"/>
			</geometry>
			<origin xyz="0 0 0" rpy="0 0 0"/>
			<material name="black"/>
		</visual>
		<collision>
			<geometry>
				<cylinder radius="0.1" length="0.05"/>
			</geometry>
		</collision>
		<inertial>
			<origin xyz="0 0 0"/>
			<mass value="0.500"/>
			<inertia ixx="0.0013541667" ixy="0" ixz="0" iyy="0.0013541667" iyz="0" izz="0.0025"/>
		</inertial>
	</link>

	<joint name="left_wheel_joint" type="continuous">
		<parent link="base_link"/>
		<child link="left_wheel_link"/>
		<origin rpy="-1.5707 0 0" xyz="-0.100 0.130 0"/>
		<axis xyz="0 0 1"/>
	</joint>

	<link name="right_wheel_link">
		<visual>
			<geometry>
				<cylinder radius="0.1" length="0.05"/>
			</geometry>
			<origin xyz="0 0 0" rpy="0 0 0"/>
			<material name="black"/>
		</visual>
		<collision>
			<geometry>
				<cylinder radius="0.1" length="0.05"/>
			</geometry>
		</collision>
		<inertial>
			<origin xyz="0 0 0"/>
			<mass value="0.500"/>
			<inertia ixx="0.0013541667" ixy="0" ixz="0" iyy="0.0013541667" iyz="0" izz="0.0025"/>
		</inertial>
	</link>

	<joint name="right_wheel_joint" type="continuous">
		<parent link="base_link"/>
		<child link="right_wheel_link"/>
		<origin rpy="1.5707 0 0" xyz="-0.100 -0.130 0"/>
		<axis xyz="0 0 -1"/>
	</joint>
	
	<link name="caster_link">
		<visual>
			<geometry>
				<sphere radius="0.05"/>
			</geometry>
			<material name="green">
				<color rgba="0 1 0 1"/>
			</material>
		</visual>
		<collision>
			<geometry>
				<sphere radius="0.05"/>
			</geometry>
		</collision>
		<inertial>
			<origin xyz="0 0 0"/>
			<mass value="0.500"/>
			<inertia ixx="0.00025" ixy="0" ixz="0" iyy="0.00025"  iyz="0" izz="0.00025"/>
		</inertial>
	</link>
	
	<joint name="caster_joint" type="fixed">
		<parent link="base_link"/>
		<child link="caster_link"/>
		<origin xyz="0.150 0 -0.050"/>
	</joint>

	<link name="base_footprint"/>
	
	<joint name="base_link_joint" type="fixed">
		<parent link="base_footprint"/>
		<child link="base_link"/>
		<origin xyz="0 0 0.100"/>
	</joint>
		
<!-- Camera -->
	<link name="camera_link">
		<collision>
			<origin xyz="0 0 0" rpy="0 0 0"/>
			<geometry>
				<box size="0.1 0.1 0.1"/>
			</geometry>
		</collision>
		<visual>
			<origin xyz="0 0 0" rpy="0 0 0"/>
			<geometry>
				<box size="0.1 0.1 0.1"/>
			</geometry>
			<material name="red"/>
		</visual>
		<inertial>
			<mass value="1e-5" />
			<origin xyz="0 0 0" rpy="0 0 0"/>
			<inertia ixx="1e-6" ixy="0" ixz="0" iyy="1e-6" iyz="0" izz="1e-6" />
		</inertial>
	</link>

	<joint name="camera_joint" type="fixed">
		<parent link="base_link"/>
		<child link="camera_link"/>
		<origin rpy="0 0 0" xyz="0 0 0.1"/>
		<axis xyz="0 1 0" />
	</joint>

	<!-- ===============  Transmission =============== -->
	<transmission name="left_wheel_trans">
		<type>transmission_interface/SimpleTransmission</type>
		<joint name="left_wheel_joint">
			<hardwareInterface>VelocityJointInterface</hardwareInterface>
		</joint>
		<actuator name="left_wheel_motor">
			<hardwareInterface>VelocityJointInterface</hardwareInterface>
			<mechanicalReduction>30</mechanicalReduction>
		</actuator>
	</transmission>
	
	<transmission name="right_wheel_trans">
		<type>transmission_interface/SimpleTransmission</type>
		<joint name="right_wheel_joint">
			<hardwareInterface>VelocityJointInterface</hardwareInterface>
		</joint>
		<actuator name="right_wheel_motor">
			<hardwareInterface>VelocityJointInterface</hardwareInterface>
			<mechanicalReduction>30</mechanicalReduction>
		</actuator>
	</transmission>

	<!-- =============== Gazebo =============== -->
	<gazebo>
		<plugin name="gazebo_ros_control" filename="libgazebo_ros_control.so">
			<robotNamespace>my_robo</robotNamespace>
		</plugin>
	</gazebo>
	
	<gazebo reference="base_link">
		<selfCollide>true</selfCollide>
		<mu1 value="0.05" />
		<mu2 value="0.05" />
	</gazebo>
	
	<gazebo reference="left_wheel_link">
		<selfCollide>true</selfCollide>
		<mu1 value="0.8" />
		<mu2 value="0.8" />
	</gazebo>

	
	<gazebo reference="right_wheel_link">
		<selfCollide>true</selfCollide>
		<mu1 value="0.8" />
		<mu2 value="0.8" />
	</gazebo>
	
	<gazebo reference="caster_link">
		<selfCollide>true</selfCollide>
		<!-- This caster is no frictional resistance. -->
		<mu1 value="0.0" />
		<mu2 value="0.0" />
	</gazebo>

	<gazebo reference="camera_link">
		<sensor type="camera" name="camera1">
			<update_rate>30.0</update_rate>
			<camera name="head">
				<horizontal_fov>1.3962634</horizontal_fov>
				<image>
					<width>800</width>
					<height>800</height>
					<format>R8G8B8</format>
				</image>
				<clip>
					<near>0.02</near>
					<far>300</far>
				</clip>
				<noise>
					<type>gaussian</type>
					<!-- Noise is sampled independently per pixel on each frame.
					That pixel's noise value is added to each of its color
					channels, which at that point lie in the range [0,1]. -->
					<mean>0.0</mean>
					<stddev>0.007</stddev>
				</noise>
			</camera>
			<plugin name="camera_controller" filename="libgazebo_ros_camera.so">
				<alwaysOn>true</alwaysOn>
				<updateRate>0.0</updateRate>
				<cameraName>rrbot/camera1</cameraName>
				<imageTopicName>image_raw</imageTopicName>
				<cameraInfoTopicName>camera_info</cameraInfoTopicName>
				<frameName>camera_link</frameName>
				<hackBaseline>0.07</hackBaseline>
				<distortionK1>0.0</distortionK1>
				<distortionK2>0.0</distortionK2>
				<distortionK3>0.0</distortionK3>
				<distortionT1>0.0</distortionT1>
				<distortionT2>0.0</distortionT2>
			</plugin>
		</sensor>
	</gazebo>
</robot>
